<?xml version="1.0" ?>
<!-- =================================================================================== -->
<!-- |    This document was autogenerated by xacro from robots/human_hand.urdf.xacro   | -->
<!-- |    EDITING THIS FILE BY HAND IS NOT RECOMMENDED                                 | -->
<!-- =================================================================================== -->
<robot name="human_hand" xmlns:xacro="http://www.ros.org/wiki/xacro">
  <!--
	    HUMAN HAND MODEL v 0.1
	    urdf derived from human Pisa SoftHand
	    author Guillaume Walck, Robert Haschke
	    meshes from GrabCAD, author Joerg Schmit
	    original CAD model available at: https://grabcad.com/library/human-left-hand/
	-->
  <material name="HumanHand/Skin">
    <color rgba="0.802 0.732 0.673 1.0"/>
  </material>
  <link name="glove_base"/>
  <!-- PALM -->
  <joint name="palm_joint" type="fixed">
    <origin rpy="0 0 0" xyz="0 0 0"/>
    <parent link="glove_base"/>
    <child link="palm_link"/>
  </joint>
  <link name="palm_link">
    <visual>
      <geometry>
        <mesh filename="human_hand/palm.stl" scale=" 0.001 .001 .001"/>
      </geometry>
      <material name="HumanHand/Skin"/>
    </visual>
  </link>
  <!-- THUMB AND FINGERS -->
  <!-- KNUCKLE -->
  <joint name="thumb_abduction_joint" type="revolute">
    <origin rpy="0.0 0.624 0" xyz="0.02475 -0.0125 0.0125"/>
    <parent link="palm_link"/>
    <child link="thumb_knuckle_link"/>
    <axis xyz="1 0 0"/>
    <limit effort="100" lower="0.0" upper="1.57079632679" velocity="100"/>
    <dynamics damping="0.0" friction="0.0"/>
  </joint>
  <link name="thumb_knuckle_link">
  </link>
  <!-- PROXIMAL PHALANGE -->
  <joint name="thumb_proximal_joint" type="revolute">
    <origin rpy="0 0 0" xyz="0 0 0"/>
    <parent link="thumb_knuckle_link"/>
    <child link="thumb_proximal_link"/>
    <axis xyz="0 -1 0"/>
    <limit effort="100" lower="-0.7" upper="0.8" velocity="100"/>
    <dynamics damping="0.0" friction="0.0"/>
  </joint>
  <link name="thumb_proximal_link">
    <visual>
      <geometry>
        <mesh filename="human_hand/thumb_proximal.stl" scale="0.001 0.001 .001"/>
      </geometry>
      <material name="HumanHand/Skin"/>
    </visual>
  </link>
  <!-- MIDDLE PHALANGE -->
  <joint name="thumb_middle_joint" type="revolute">
    <origin rpy="0 0 0" xyz="0 0 0.05415"/>
    <parent link="thumb_proximal_link"/>
    <child link="thumb_middle_link"/>
    <axis xyz="0 -1 0"/>
    <limit effort="100" lower="0.0" upper="1.57079632679" velocity="100"/>
    <dynamics damping="0.0" friction="0.0"/>
  </joint>
  <link name="thumb_middle_link">
    <visual>
      <geometry>
        <mesh filename="human_hand/thumb_middle.stl" scale="0.001 0.001 .001"/>
      </geometry>
      <material name="HumanHand/Skin"/>
    </visual>
  </link>
  <!-- DISTAL PHALANGE -->
  <joint name="thumb_distal_joint" type="revolute">
    <origin rpy="0 0 0" xyz="0 0 0.03803"/>
    <parent link="thumb_middle_link"/>
    <child link="thumb_distal_link"/>
    <axis xyz="0 -1 0"/>
    <limit effort="100" lower="0.0" upper="1.57079632679" velocity="100"/>
    <dynamics damping="0.0" friction="0.0"/>
  </joint>
  <link name="thumb_distal_link">
    <visual>
      <geometry>
        <mesh filename="human_hand/thumb_distal.stl" scale="0.001 0.001 .001"/>
      </geometry>
      <material name="HumanHand/Skin"/>
    </visual>
  </link>
  <!-- KNUCKLE -->
  <joint name="index_abduction_joint" type="revolute">
    <origin rpy="0 0 0" xyz="0.02175 -0.002 0.099"/>
    <parent link="palm_link"/>
    <child link="index_knuckle_link"/>
    <axis xyz="0 -1 0"/>
    <limit effort="100" lower="-0.523598775598" upper="0.523598775598" velocity="100"/>
    <dynamics damping="0.0" friction="0.0"/>
  </joint>
  <link name="index_knuckle_link">
  </link>
  <!-- PROXIMAL PHALANGE -->
  <joint name="index_proximal_joint" type="revolute">
    <origin rpy="0 0 0" xyz="0 0 0"/>
    <parent link="index_knuckle_link"/>
    <child link="index_proximal_link"/>
    <axis xyz="1 0 0"/>
    <limit effort="100" lower="0.0" upper="1.57079632679" velocity="100"/>
    <dynamics damping="0.0" friction="0.0"/>
  </joint>
  <link name="index_proximal_link">
    <visual>
      <geometry>
        <mesh filename="human_hand/index_proximal.stl" scale="0.001 0.001 .001"/>
      </geometry>
      <material name="HumanHand/Skin"/>
    </visual>
  </link>
  <!-- MIDDLE PHALANGE -->
  <joint name="index_middle_joint" type="revolute">
    <origin rpy="0 0 0" xyz="0 0 0.046"/>
    <parent link="index_proximal_link"/>
    <child link="index_middle_link"/>
    <axis xyz="1 0 0"/>
    <limit effort="100" lower="0.0" upper="1.57079632679" velocity="100"/>
    <dynamics damping="0.0" friction="0.0"/>
  </joint>
  <link name="index_middle_link">
    <visual>
      <geometry>
        <mesh filename="human_hand/index_middle.stl" scale="0.001 0.001 .001"/>
      </geometry>
      <material name="HumanHand/Skin"/>
    </visual>
  </link>
  <!-- DISTAL PHALANGE -->
  <joint name="index_distal_joint" type="revolute">
    <origin rpy="0 0 0" xyz="0 0 0.027"/>
    <parent link="index_middle_link"/>
    <child link="index_distal_link"/>
    <axis xyz="1 0 0"/>
    <limit effort="100" lower="0.0" upper="1.57079632679" velocity="100"/>
    <dynamics damping="0.0" friction="0.0"/>
  </joint>
  <link name="index_distal_link">
    <visual>
      <geometry>
        <mesh filename="human_hand/index_distal.stl" scale="0.001 0.001 .001"/>
      </geometry>
      <material name="HumanHand/Skin"/>
    </visual>
  </link>
  <!-- KNUCKLE -->
  <joint name="middle_abduction_joint" type="revolute">
    <origin rpy="0 0 0" xyz="-0.002 0.0015 0.0955"/>
    <parent link="palm_link"/>
    <child link="middle_knuckle_link"/>
    <axis xyz="0 -1 0"/>
    <limit effort="100" lower="-0.523598775598" upper="0.523598775598" velocity="100"/>
    <dynamics damping="0.0" friction="0.0"/>
  </joint>
  <link name="middle_knuckle_link">
  </link>
  <!-- PROXIMAL PHALANGE -->
  <joint name="middle_proximal_joint" type="revolute">
    <origin rpy="0 0 0" xyz="0 0 0"/>
    <parent link="middle_knuckle_link"/>
    <child link="middle_proximal_link"/>
    <axis xyz="1 0 0"/>
    <limit effort="100" lower="0.0" upper="1.57079632679" velocity="100"/>
    <dynamics damping="0.0" friction="0.0"/>
  </joint>
  <link name="middle_proximal_link">
    <visual>
      <geometry>
        <mesh filename="human_hand/middle_proximal.stl" scale="0.001 0.001 .001"/>
      </geometry>
      <material name="HumanHand/Skin"/>
    </visual>
  </link>
  <!-- MIDDLE PHALANGE -->
  <joint name="middle_middle_joint" type="revolute">
    <origin rpy="0 0 0" xyz="0 0 0.0495"/>
    <parent link="middle_proximal_link"/>
    <child link="middle_middle_link"/>
    <axis xyz="1 0 0"/>
    <limit effort="100" lower="0.0" upper="1.57079632679" velocity="100"/>
    <dynamics damping="0.0" friction="0.0"/>
  </joint>
  <link name="middle_middle_link">
    <visual>
      <geometry>
        <mesh filename="human_hand/middle_middle.stl" scale="0.001 0.001 .001"/>
      </geometry>
      <material name="HumanHand/Skin"/>
    </visual>
  </link>
  <!-- DISTAL PHALANGE -->
  <joint name="middle_distal_joint" type="revolute">
    <origin rpy="0 0 0" xyz="0 0 0.033"/>
    <parent link="middle_middle_link"/>
    <child link="middle_distal_link"/>
    <axis xyz="1 0 0"/>
    <limit effort="100" lower="0.0" upper="1.57079632679" velocity="100"/>
    <dynamics damping="0.0" friction="0.0"/>
  </joint>
  <link name="middle_distal_link">
    <visual>
      <geometry>
        <mesh filename="human_hand/middle_distal.stl" scale="0.001 0.001 .001"/>
      </geometry>
      <material name="HumanHand/Skin"/>
    </visual>
  </link>
  <!-- KNUCKLE -->
  <joint name="ring_abduction_joint" type="revolute">
    <origin rpy="0 0 0" xyz="-0.02225 0.0010 0.090"/>
    <parent link="palm_link"/>
    <child link="ring_knuckle_link"/>
    <axis xyz="0 -1 0"/>
    <limit effort="100" lower="-0.523598775598" upper="0.523598775598" velocity="100"/>
    <dynamics damping="0.0" friction="0.0"/>
  </joint>
  <link name="ring_knuckle_link">
  </link>
  <!-- PROXIMAL PHALANGE -->
  <joint name="ring_proximal_joint" type="revolute">
    <origin rpy="0 0 0" xyz="0 0 0"/>
    <parent link="ring_knuckle_link"/>
    <child link="ring_proximal_link"/>
    <axis xyz="1 0 0"/>
    <limit effort="100" lower="0.0" upper="1.57079632679" velocity="100"/>
    <dynamics damping="0.0" friction="0.0"/>
  </joint>
  <link name="ring_proximal_link">
    <visual>
      <geometry>
        <mesh filename="human_hand/ring_proximal.stl" scale="0.001 0.001 .001"/>
      </geometry>
      <material name="HumanHand/Skin"/>
    </visual>
  </link>
  <!-- MIDDLE PHALANGE -->
  <joint name="ring_middle_joint" type="revolute">
    <origin rpy="0 0 0" xyz="0 0 0.048"/>
    <parent link="ring_proximal_link"/>
    <child link="ring_middle_link"/>
    <axis xyz="1 0 0"/>
    <limit effort="100" lower="0.0" upper="1.57079632679" velocity="100"/>
    <dynamics damping="0.0" friction="0.0"/>
  </joint>
  <link name="ring_middle_link">
    <visual>
      <geometry>
        <mesh filename="human_hand/ring_middle.stl" scale="0.001 0.001 .001"/>
      </geometry>
      <material name="HumanHand/Skin"/>
    </visual>
  </link>
  <!-- DISTAL PHALANGE -->
  <joint name="ring_distal_joint" type="revolute">
    <origin rpy="0 0 0" xyz="0 0 0.033"/>
    <parent link="ring_middle_link"/>
    <child link="ring_distal_link"/>
    <axis xyz="1 0 0"/>
    <limit effort="100" lower="0.0" upper="1.57079632679" velocity="100"/>
    <dynamics damping="0.0" friction="0.0"/>
  </joint>
  <link name="ring_distal_link">
    <visual>
      <geometry>
        <mesh filename="human_hand/ring_distal.stl" scale="0.001 0.001 .001"/>
      </geometry>
      <material name="HumanHand/Skin"/>
    </visual>
  </link>
  <!-- KNUCKLE -->
  <joint name="little_abduction_joint" type="revolute">
    <origin rpy="0 0 0" xyz="-0.04175 -0.003 0.079"/>
    <parent link="palm_link"/>
    <child link="little_knuckle_link"/>
    <axis xyz="0 -1 0"/>
    <limit effort="100" lower="-0.523598775598" upper="0.523598775598" velocity="100"/>
    <dynamics damping="0.0" friction="0.0"/>
  </joint>
  <link name="little_knuckle_link">
  </link>
  <!-- PROXIMAL PHALANGE -->
  <joint name="little_proximal_joint" type="revolute">
    <origin rpy="0 0 0" xyz="0 0 0"/>
    <parent link="little_knuckle_link"/>
    <child link="little_proximal_link"/>
    <axis xyz="1 0 0"/>
    <limit effort="100" lower="0.0" upper="1.57079632679" velocity="100"/>
    <dynamics damping="0.0" friction="0.0"/>
  </joint>
  <link name="little_proximal_link">
    <visual>
      <geometry>
        <mesh filename="human_hand/little_proximal.stl" scale="0.001 0.001 .001"/>
      </geometry>
      <material name="HumanHand/Skin"/>
    </visual>
  </link>
  <!-- MIDDLE PHALANGE -->
  <joint name="little_middle_joint" type="revolute">
    <origin rpy="0 0 0" xyz="0 0 0.037"/>
    <parent link="little_proximal_link"/>
    <child link="little_middle_link"/>
    <axis xyz="1 0 0"/>
    <limit effort="100" lower="0.0" upper="1.57079632679" velocity="100"/>
    <dynamics damping="0.0" friction="0.0"/>
  </joint>
  <link name="little_middle_link">
    <visual>
      <geometry>
        <mesh filename="human_hand/little_middle.stl" scale="0.001 0.001 .001"/>
      </geometry>
      <material name="HumanHand/Skin"/>
    </visual>
  </link>
  <!-- DISTAL PHALANGE -->
  <joint name="little_distal_joint" type="revolute">
    <origin rpy="0 0 0" xyz="0 0 0.0215"/>
    <parent link="little_middle_link"/>
    <child link="little_distal_link"/>
    <axis xyz="1 0 0"/>
    <limit effort="100" lower="0.0" upper="1.57079632679" velocity="100"/>
    <dynamics damping="0.0" friction="0.0"/>
  </joint>
  <link name="little_distal_link">
    <visual>
      <geometry>
        <mesh filename="human_hand/little_distal.stl" scale="0.001 0.001 .001"/>
      </geometry>
      <material name="HumanHand/Skin"/>
    </visual>
  </link>
  <!-- TACTILE MARKERS -->
  <klampt package_root="." use_vis_geom="1">
    <noselfcollision pairs = "6 8 6 12 6 16 6 20 6 24  8 16  12 20  16 20"/>
  <klampt/>
</robot>